Workbook

Sheet README
A1: User Study Replication Workbook (BIS-only variant)
A3: All calculations are derived from per-participant questionnaire
A4: responses (one row per participant, 85 rows total).
A6: Sheets
A7: Participants 85 valid participants (40 expert, 45 non-expert)
A8: SUS 85 per-participant SUS item responses + score
A9: TLX 85 per-participant NASA-TLX subscale responses
A10: TOAST 85 per-participant TOAST item responses + factors
A11: Sessions 510 scenario sessions (outcomes + timings)
A12: PerParticipant Per-participant aggregates (formulas)
A13: Analysis Cronbach's alpha, between-group tests, behavioural
A14: InterRater Cohen's kappa (evaluator_1 vs evaluator_2)
... A23: - Cohen's kappa computed on the full set of 510 sessions.

Sheet Participants
A1: participant_id | B1: user_type | C1: lang | D1: age | E1: gender | F1: education | G1: computer_skills | H1: ifttt_familiarity | I1: quality_flag
A2: user_0001 | B2: non_expert | C2: it | D2: 18 | E2: F | F2: Scuola superiore
A3: user_0002 | B3: non_expert | C3: it | D3: 18 | E3: F | F3: Scuola superiore
A4: user_0003 | B4: non_expert | C4: it | D4: 18 | E4: M | F4: Scuola superiore
A5: user_0004 | B5: non_expert | C5: it | D5: 18 | E5: M | F5: Scuola superiore
A6: user_0005 | B6: non_expert | C6: it | D6: 18 | E6: M | F6: Scuola superiore
A7: user_0006 | B7: non_expert | C7: it | D7: 18 | E7: M | F7: Scuola superiore
A8: user_0007 | B8: non_expert | C8: it | D8: 18 | E8: F | F8: Scuola superiore
A9: user_0008 | B9: non_expert | C9: it | D9: 18 | E9: M | F9: Scuola superiore
A10: user_0009 | B10: non_expert | C10: it | D10: 18 | E10: M | F10: Scuola superiore | I10: outlier_contradictory
A11: user_0010 | B11: non_expert | C11: it | D11: 18 | E11: M | F11: Scuola superiore
A12: user_0011 | B12: non_expert | C12: it | D12: 18 | E12: M | F12: Scuola superiore
A13: user_0013 | B13: non_expert | C13: it | D13: 18 | E13: M | F13: Scuola superiore
A14: user_0015 | B14: non_expert | C14: it | D14: 18 | E14: F | F14: Scuola superiore | I14: low_quality_repeat
A15: user_0016 | B15: non_expert | C15: it | D15: 18 | E15: M | F15: Scuola superiore
A16: user_0017 | B16: non_expert | C16: it | D16: 18 | E16: M | F16: Scuola superiore
A17: user_0018 | B17: non_expert | C17: it | D17: 18 | E17: M | F17: Scuola superiore
A18: user_0019 | B18: non_expert | C18: it | D18: 18 | E18: F | F18: Scuola superiore
A19: user_0020 | B19: non_expert | C19: it | D19: 18 | E19: M | F19: Scuola superiore
A20: user_0021 | B20: non_expert | C20: it | D20: 18 | E20: Maschio | F20: Scuola superiore | G20: 3 | H20: 1
A21: user_0022 | B21: non_expert | C21: it | D21: 18 | E21: Maschio | F21: Scuola superiore | G21: 2 | H21: 1
A22: user_0023 | B22: non_expert | C22: it | D22: 18 | E22: Maschio | F22: Scuola superiore | G22: 2 | H22: 1
A23: user_0024 | B23: non_expert | C23: it | D23: 18 | E23: Maschio | F23: Scuola superiore | G23: 2 | H23: 1
A24: user_0026 | B24: non_expert | C24: it | D24: 18 | E24: Maschio | F24: Scuola superiore | G24: 3 | H24: 1 | I24: outlier_speed
A25: user_0027 | B25: non_expert | C25: it | D25: 18 | E25: Maschio | F25: Scuola superiore | G25: 2 | H25: 1
A26: user_0028 | B26: non_expert | C26: it | D26: 18 | E26: Maschio | F26: Scuola superiore | G26: 2 | H26: 1
A27: user_0029 | B27: non_expert | C27: it | D27: 18 | E27: Maschio | F27: Scuola superiore | G27: 2 | H27: 1
A28: user_0031 | B28: non_expert | C28: it | D28: 18 | E28: Maschio | F28: Scuola superiore | G28: 3 | H28: 1
A29: user_0032 | B29: non_expert | C29: it | D29: 18 | E29: Maschio | F29: Scuola superiore | G29: 3 | H29: 1
A30: user_0033 | B30: non_expert | C30: it | D30: 18 | E30: Maschio | F30: Scuola superiore | G30: 2 | H30: 1
A31: user_0034 | B31: non_expert | C31: it | D31: 18 | E31: Maschio | F31: Scuola superiore | G31: 3 | H31: 1
A32: user_0037 | B32: non_expert | C32: it | D32: 18 | E32: Maschio | F32: Scuola superiore | G32: 1 | H32: 1
A33: user_0039 | B33: non_expert | C33: it | D33: 18 | E33: Maschio | F33: Scuola superiore | G33: 1 | H33: 1
A34: user_0042 | B34: non_expert | C34: it | D34: 18 | E34: Maschio | F34: Scuola superiore | G34: 1 | H34: 1
A35: user_0043 | B35: non_expert | C35: it | D35: 18 | E35: Maschio | F35: Scuola superiore | G35: 1 | H35: 1
A36: user_0045 | B36: non_expert | C36: it | D36: 18 | E36: Maschio | F36: Scuola superiore | G36: 1 | H36: 1
... A42: user_0051 | B42: non_expert | C42: it | D42: 18 | E42: Maschio | F42: Scuola superiore | G42: 1 | H42: 1
A43: user_0055 | B43: non_expert | C43: it | D43: 18 | E43: Maschio | F43: Scuola superiore | G43: 1 | H43: 1 | I43: outlier_tlx_max
A44: user_0061 | B44: non_expert | C44: it | D44: 18 | E44: Maschio | F44: Scuola superiore | G44: 1 | H44: 1 | I44: low_quality_all_same
A45: user_0065 | B45: non_expert | C45: it | D45: 35 | E45: Preferisco non dire | F45: Laurea triennale | G45: 5 | H45: 1 | I45: outlier_contradictory
...

Sheet SUS
A1: participant_id | B1: item_1 | C1: item_2 | D1: item_3 | E1: item_4 | F1: item_5 | G1: item_6 | H1: item_7 | I1: item_8 | J1: item_9 | K1: item_10 | L1: t_1 | M1: t_2 | N1: t_3 | O1: t_4 | P1: t_5 | Q1: t_6 | R1: t_7 | S1: t_8 | T1: t_9 | U1: t_10 | V1: sum_t | W1: sus_score | X1: user_type
A2: user_0001 | B2: -1.8316691 | C2: 2 | D2: 7.3316691 | E2: 2.5 | F2: 3 | G2: 3 | H2: 2.5 | I2: 3.5 | J2: 3 | K2: 2.5 | L2: =B2-1 | M2: =5-C2 | N2: =D2-1 | O2: =5-E2 | P2: =F2-1 | Q2: =5-G2 | R2: =H2-1 | S2: =5-I2 | T2: =J2-1 | U2: =5-K2 | V2: =SUM(L2:U2) | W2: =V2*2.5 | X2: =VLOOKUP(A2,Participants!$A$2:$B$86,2,FALSE)
A3: user_0002 | B3: 2 | C3: 3 | D3: 3 | E3: 2 | F3: 3 | G3: 2.5 | H3: 4 | I3: 4 | J3: 3 | K3: 1 | L3: =B3-1 | M3: =5-C3 | N3: =D3-1 | O3: =5-E3 | P3: =F3-1 | Q3: =5-G3 | R3: =H3-1 | S3: =5-I3 | T3: =J3-1 | U3: =5-K3 | V3: =SUM(L3:U3) | W3: =V3*2.5 | X3: =VLOOKUP(A3,Participants!$A$2:$B$86,2,FALSE)
A4: user_0003 | B4: 4 | C4: 3 | D4: 3 | E4: 1 | F4: 3 | G4: 1 | H4: 4 | I4: 1.5 | J4: 4 | K4: 1 | L4: =B4-1 | M4: =5-C4 | N4: =D4-1 | O4: =5-E4 | P4: =F4-1 | Q4: =5-G4 | R4: =H4-1 | S4: =5-I4 | T4: =J4-1 | U4: =5-K4 | V4: =SUM(L4:U4) | W4: =V4*2.5 | X4: =VLOOKUP(A4,Participants!$A$2:$B$86,2,FALSE)
A5: user_0004 | B5: 1.5 | C5: 2 | D5: 4.5 | E5: 1 | F5: 2.5 | G5: 3.5 | H5: 5 | I5: 2 | J5: 3 | K5: 1.5 | L5: =B5-1 | M5: =5-C5 | N5: =D5-1 | O5: =5-E5 | P5: =F5-1 | Q5: =5-G5 | R5: =H5-1 | S5: =5-I5 | T5: =J5-1 | U5: =5-K5 | V5: =SUM(L5:U5) | W5: =V5*2.5 | X5: =VLOOKUP(A5,Participants!$A$2:$B$86,2,FALSE)
A6: user_0005 | B6: 1 | C6: 1.5 | D6: 4 | E6: 1 | F6: 2.5 | G6: 1.5 | H6: 4 | I6: 1 | J6: 3.5 | K6: 1 | L6: =B6-1 | M6: =5-C6 | N6: =D6-1 | O6: =5-E6 | P6: =F6-1 | Q6: =5-G6 | R6: =H6-1 | S6: =5-I6 | T6: =J6-1 | U6: =5-K6 | V6: =SUM(L6:U6) | W6: =V6*2.5 | X6: =VLOOKUP(A6,Participants!$A$2:$B$86,2,FALSE)
A7: user_0006 | B7: 3 | C7: 2 | D7: 3.5 | E7: 3 | F7: 3 | G7: 2 | H7: 3.5 | I7: 2 | J7: 3 | K7: 2.5 | L7: =B7-1 | M7: =5-C7 | N7: =D7-1 | O7: =5-E7 | P7: =F7-1 | Q7: =5-G7 | R7: =H7-1 | S7: =5-I7 | T7: =J7-1 | U7: =5-K7 | V7: =SUM(L7:U7) | W7: =V7*2.5 | X7: =VLOOKUP(A7,Participants!$A$2:$B$86,2,FALSE)
A8: user_0007 | B8: 3 | C8: 3 | D8: 2.5 | E8: 3.5 | F8: 2.5 | G8: 3.5 | H8: 1.5 | I8: 3 | J8: 3 | K8: 3 | L8: =B8-1 | M8: =5-C8 | N8: =D8-1 | O8: =5-E8 | P8: =F8-1 | Q8: =5-G8 | R8: =H8-1 | S8: =5-I8 | T8: =J8-1 | U8: =5-K8 | V8: =SUM(L8:U8) | W8: =V8*2.5 | X8: =VLOOKUP(A8,Participants!$A$2:$B$86,2,FALSE)
A9: user_0008 | B9: 2 | C9: 2 | D9: 3 | E9: 2 | F9: 4.5 | G9: 1 | H9: 2 | I9: 1 | J9: 4 | K9: 2 | L9: =B9-1 | M9: =5-C9 | N9: =D9-1 | O9: =5-E9 | P9: =F9-1 | Q9: =5-G9 | R9: =H9-1 | S9: =5-I9 | T9: =J9-1 | U9: =5-K9 | V9: =SUM(L9:U9) | W9: =V9*2.5 | X9: =VLOOKUP(A9,Participants!$A$2:$B$86,2,FALSE)
A10: user_0009 | B10: 4.5 | C10: 2 | D10: 4 | E10: 3 | F10: 4 | G10: 2 | H10: 3.5 | I10: 2 | J10: 4 | K10: 2 | L10: =B10-1 | M10: =5-C10 | N10: =D10-1 | O10: =5-E10 | P10: =F10-1 | Q10: =5-G10 | R10: =H10-1 | S10: =5-I10 | T10: =J10-1 | U10: =5-K10 | V10: =SUM(L10:U10) | W10: =V10*2.5 | X10: =VLOOKUP(A10,Participants!$A$2:$B$86,2,FALSE)
A11: user_0010 | B11: 4.5 | C11: 5 | D11: 4.5 | E11: 3 | F11: 4.5 | G11: 1.5 | H11: 3 | I11: 1.5 | J11: 3.5 | K11: 2.5 | L11: =B11-1 | M11: =5-C11 | N11: =D11-1 | O11: =5-E11 | P11: =F11-1 | Q11: =5-G11 | R11: =H11-1 | S11: =5-I11 | T11: =J11-1 | U11: =5-K11 | V11: =SUM(L11:U11) | W11: =V11*2.5 | X11: =VLOOKUP(A11,Participants!$A$2:$B$86,2,FALSE)
A12: user_0011 | B12: 4 | C12: 2 | D12: 4.5 | E12: 3 | F12: 4 | G12: 2.5 | H12: 3.5 | I12: 4 | J12: 4 | K12: 2 | L12: =B12-1 | M12: =5-C12 | N12: =D12-1 | O12: =5-E12 | P12: =F12-1 | Q12: =5-G12 | R12: =H12-1 | S12: =5-I12 | T12: =J12-1 | U12: =5-K12 | V12: =SUM(L12:U12) | W12: =V12*2.5 | X12: =VLOOKUP(A12,Participants!$A$2:$B$86,2,FALSE)
A13: user_0013 | B13: 4 | C13: 3.5 | D13: 3 | E13: 1.5 | F13: 2.5 | G13: 2.5 | H13: 2 | I13: 3.5 | J13: 3.5 | K13: 1.5 | L13: =B13-1 | M13: =5-C13 | N13: =D13-1 | O13: =5-E13 | P13: =F13-1 | Q13: =5-G13 | R13: =H13-1 | S13: =5-I13 | T13: =J13-1 | U13: =5-K13 | V13: =SUM(L13:U13) | W13: =V13*2.5 | X13: =VLOOKUP(A13,Participants!$A$2:$B$86,2,FALSE)
... A86: user_0205 | B86: 4 | C86: 1.5 | D86: 4.5 | E86: 1.5 | F86: 4 | G86: 3 | H86: 5 | I86: 2.5 | J86: 4.5 | K86: 1 | L86: =B86-1 | M86: =5-C86 | N86: =D86-1 | O86: =5-E86 | P86: =F86-1 | Q86: =5-G86 | R86: =H86-1 | S86: =5-I86 | T86: =J86-1 | U86: =5-K86 | V86: =SUM(L86:U86) | W86: =V86*2.5 | X86: =VLOOKUP(A86,Participants!$A$2:$B$86,2,FALSE)

Sheet TLX
A1: participant_id | B1: mental_demand | C1: physical_demand | D1: temporal_demand | E1: performance | F1: effort | G1: frustration | H1: raw_tlx_overall | I1: user_type
A2: user_0001 | B2: 60 | C2: 0 | D2: 57.5 | E2: 57.5 | F2: 52.5 | G2: 45 | H2: =AVERAGE(B2:G2) | I2: =VLOOKUP(A2,Participants!$A$2:$B$86,2,FALSE)
A3: user_0002 | B3: 65 | C3: 0 | D3: 32.5 | E3: 57.5 | F3: 17.5 | G3: 32.5 | H3: =AVERAGE(B3:G3) | I3: =VLOOKUP(A3,Participants!$A$2:$B$86,2,FALSE)
A4: user_0003 | B4: 40 | C4: 0 | D4: 2.5 | E4: 87.5 | F4: 40 | G4: 5 | H4: =AVERAGE(B4:G4) | I4: =VLOOKUP(A4,Participants!$A$2:$B$86,2,FALSE)
A5: user_0004 | B5: 5 | C5: 0 | D5: 0 | E5: 82.5 | F5: 2.5 | G5: 2.5 | H5: =AVERAGE(B5:G5) | I5: =VLOOKUP(A5,Participants!$A$2:$B$86,2,FALSE)
A6: user_0005 | B6: 10 | C6: 0 | D6: 0 | E6: 30 | F6: 2.5 | G6: 5 | H6: =AVERAGE(B6:G6) | I6: =VLOOKUP(A6,Participants!$A$2:$B$86,2,FALSE)
A7: user_0006 | B7: 35 | C7: 0 | D7: 25 | E7: 75 | F7: 50 | G7: 25 | H7: =AVERAGE(B7:G7) | I7: =VLOOKUP(A7,Participants!$A$2:$B$86,2,FALSE)
A8: user_0007 | B8: 85 | C8: 0 | D8: 95 | E8: 32.5 | F8: 82.5 | G8: 60 | H8: =AVERAGE(B8:G8) | I8: =VLOOKUP(A8,Participants!$A$2:$B$86,2,FALSE)
A9: user_0008 | B9: 47.5 | C9: 0 | D9: 12.5 | E9: 50 | F9: 15 | G9: 2.5 | H9: =AVERAGE(B9:G9) | I9: =VLOOKUP(A9,Participants!$A$2:$B$86,2,FALSE)
A10: user_0009 | B10: 42.5 | C10: 0 | D10: 50 | E10: 72.5 | F10: 45 | G10: 37.5 | H10: =AVERAGE(B10:G10) | I10: =VLOOKUP(A10,Participants!$A$2:$B$86,2,FALSE)
A11: user_0010 | B11: 40 | C11: 0 | D11: 47.5 | E11: 85 | F11: 32.5 | G11: 32.5 | H11: =AVERAGE(B11:G11) | I11: =VLOOKUP(A11,Participants!$A$2:$B$86,2,FALSE)
A12: user_0011 | B12: 17.5 | C12: 0 | D12: 15 | E12: 72.5 | F12: 17.5 | G12: 17.5 | H12: =AVERAGE(B12:G12) | I12: =VLOOKUP(A12,Participants!$A$2:$B$86,2,FALSE)
A13: user_0013 | B13: 5 | C13: 0 | D13: 5 | E13: 62.5 | F13: 15 | G13: 7.5 | H13: =AVERAGE(B13:G13) | I13: =VLOOKUP(A13,Participants!$A$2:$B$86,2,FALSE)
... A86: user_0205 | B86: 10 | C86: 0 | D86: 2.5 | E86: 85 | F86: 10 | G86: 2.5 | H86: =AVERAGE(B86:G86) | I86: =VLOOKUP(A86,Participants!$A$2:$B$86,2,FALSE)

Sheet TOAST
A1: participant_id | B1: item_1 | C1: item_2 | D1: item_3 | E1: item_4 | F1: item_5 | G1: item_6 | H1: item_7 | I1: item_8 | J1: item_9 | K1: understanding | L1: performance | M1: overall | N1: user_type | O1: sum_u_wojton
A2: user_0001 | B2: 9.9421431 | C2: 4.5 | D2: 3.3886209 | E2: 5 | F2: 9.0085889 | G2: 5 | H2: 0.99141105 | I2: -2.830764 | J2: 5 | K2: =AVERAGE(B2,D2,E2,I2) | L2: =AVERAGE(C2,F2,G2,H2,J2) | M2: =AVERAGE(B2:J2) | N2: =VLOOKUP(A2,Participants!$A$2:$B$86,2,FALSE) | O2: =B2+C2+D2+E2
A3: user_0002 | B3: 5 | C3: 5 | D3: 4.5 | E3: 3.5 | F3: 5 | G3: 5.5 | H3: 5 | I3: 6 | J3: 4 | K3: =AVERAGE(B3,D3,E3,I3) | L3: =AVERAGE(C3,F3,G3,H3,J3) | M3: =AVERAGE(B3:J3) | N3: =VLOOKUP(A3,Participants!$A$2:$B$86,2,FALSE) | O3: =B3+C3+D3+E3
A4: user_0003 | B4: 5.5 | C4: 4.5 | D4: 5 | E4: 4.5 | F4: 6.5 | G4: 6.5 | H4: 5.5 | I4: 6.5 | J4: 6 | K4: =AVERAGE(B4,D4,E4,I4) | L4: =AVERAGE(C4,F4,G4,H4,J4) | M4: =AVERAGE(B4:J4) | N4: =VLOOKUP(A4,Participants!$A$2:$B$86,2,FALSE) | O4: =B4+C4+D4+E4
A5: user_0004 | B5: 6 | C5: 5.5 | D5: 5 | E5: 4.5 | F5: 5.5 | G5: 4.5 | H5: 4.5 | I5: 3 | J5: 4 | K5: =AVERAGE(B5,D5,E5,I5) | L5: =AVERAGE(C5,F5,G5,H5,J5) | M5: =AVERAGE(B5:J5) | N5: =VLOOKUP(A5,Participants!$A$2:$B$86,2,FALSE) | O5: =B5+C5+D5+E5
A6: user_0005 | B6: 5.5 | C6: 4.5 | D6: 5.5 | E6: 4.5 | F6: 5 | G6: 4 | H6: 5 | I6: 4.5 | J6: 4.5 | K6: =AVERAGE(B6,D6,E6,I6) | L6: =AVERAGE(C6,F6,G6,H6,J6) | M6: =AVERAGE(B6:J6) | N6: =VLOOKUP(A6,Participants!$A$2:$B$86,2,FALSE) | O6: =B6+C6+D6+E6
A7: user_0006 | B7: 4 | C7: 3.5 | D7: 3.5 | E7: 4 | F7: 4 | G7: 4 | H7: 4 | I7: 4.5 | J7: 4 | K7: =AVERAGE(B7,D7,E7,I7) | L7: =AVERAGE(C7,F7,G7,H7,J7) | M7: =AVERAGE(B7:J7) | N7: =VLOOKUP(A7,Participants!$A$2:$B$86,2,FALSE) | O7: =B7+C7+D7+E7
A8: user_0007 | B8: 5 | C8: 5 | D8: 5 | E8: 3 | F8: 3 | G8: 4.5 | H8: 4.5 | I8: 5 | J8: 2 | K8: =AVERAGE(B8,D8,E8,I8) | L8: =AVERAGE(C8,F8,G8,H8,J8) | M8: =AVERAGE(B8:J8) | N8: =VLOOKUP(A8,Participants!$A$2:$B$86,2,FALSE) | O8: =B8+C8+D8+E8
A9: user_0008 | B9: 4 | C9: 4 | D9: 4 | E9: 4 | F9: 4 | G9: 4 | H9: 4 | I9: 4 | J9: 4 | K9: =AVERAGE(B9,D9,E9,I9) | L9: =AVERAGE(C9,F9,G9,H9,J9) | M9: =AVERAGE(B9:J9) | N9: =VLOOKUP(A9,Participants!$A$2:$B$86,2,FALSE) | O9: =B9+C9+D9+E9
A10: user_0009 | B10: 6.5 | C10: 6 | D10: 6 | E10: 7 | F10: 6 | G10: 6.5 | H10: 6.5 | I10: 6 | J10: 6 | K10: =AVERAGE(B10,D10,E10,I10) | L10: =AVERAGE(C10,F10,G10,H10,J10) | M10: =AVERAGE(B10:J10) | N10: =VLOOKUP(A10,Participants!$A$2:$B$86,2,FALSE) | O10: =B10+C10+D10+E10
A11: user_0010 | B11: 6.5 | C11: 6.5 | D11: 6.5 | E11: 6.5 | F11: 6 | G11: 5.5 | H11: 4 | I11: 6.5 | J11: 6 | K11: =AVERAGE(B11,D11,E11,I11) | L11: =AVERAGE(C11,F11,G11,H11,J11) | M11: =AVERAGE(B11:J11) | N11: =VLOOKUP(A11,Participants!$A$2:$B$86,2,FALSE) | O11: =B11+C11+D11+E11
A12: user_0011 | B12: 4.5 | C12: 5 | D12: 4.5 | E12: 5 | F12: 5 | G12: 5 | H12: 4 | I12: 2.5 | J12: 5.5 | K12: =AVERAGE(B12,D12,E12,I12) | L12: =AVERAGE(C12,F12,G12,H12,J12) | M12: =AVERAGE(B12:J12) | N12: =VLOOKUP(A12,Participants!$A$2:$B$86,2,FALSE) | O12: =B12+C12+D12+E12
A13: user_0013 | B13: 4 | C13: 3.5 | D13: 4.5 | E13: 4.5 | F13: 4.5 | G13: 5 | H13: 3.5 | I13: 3 | J13: 4.5 | K13: =AVERAGE(B13,D13,E13,I13) | L13: =AVERAGE(C13,F13,G13,H13,J13) | M13: =AVERAGE(B13:J13) | N13: =VLOOKUP(A13,Participants!$A$2:$B$86,2,FALSE) | O13: =B13+C13+D13+E13
... A86: user_0205 | B86: 6.5 | C86: 6.5 | D86: 7 | E86: 6 | F86: 5.5 | G86: 5.5 | H86: 5 | I86: 5 | J86: 7 | K86: =AVERAGE(B86,D86,E86,I86) | L86: =AVERAGE(C86,F86,G86,H86,J86) | M86: =AVERAGE(B86:J86) | N86: =VLOOKUP(A86,Participants!$A$2:$B$86,2,FALSE) | O86: =B86+C86+D86+E86

Sheet Sessions
A1: participant_id | B1: scenario_code | C1: complexity_class | D1: scenario_index | E1: started_at | F1: completed_at | G1: total_turns | H1: total_elapsed_s | I1: attempt_number | J1: l1_syntax_ok | K1: l1_api_valid | L1: exec_pass_rate | M1: eval_behavioral_match | N1: eval_confidence | O1: eval_code_correct | P1: sandbox_all_pass | Q1: evaluator_1 | R1: evaluator_2 | S1: oracle_consensus | T1: success | U1: is_correct | V1: user_type
A2: user_0001 | B2: S1 | C2: C1 | D2: 0 | E2: 2026-03-21T10:12:13.279807+00:00 | F2: 2026-03-21T10:12:13.298546+00:00 | G2: 10 | H2: 407.31 | I2: 2 | J2: 1 | K2: 1 | M2: partially | N2: 3 | Q2: correct | R2: correct | S2: matches_completely | T2: correct | U2: =IF(T2="correct",1,0) | V2: =VLOOKUP(A2,Participants!$A$2:$B$86,2,FALSE)
A3: user_0001 | B3: M1 | C3: C2 | D3: 1 | E3: 2026-03-21T10:19:09.791128+00:00 | F3: 2026-03-21T10:19:09.810582+00:00 | G3: 8 | H3: 73.25 | I3: 2 | J3: 1 | K3: 1 | M3: partially | N3: 4 | Q3: correct | R3: correct | S3: matches_completely | T3: correct | U3: =IF(T3="correct",1,0) | V3: =VLOOKUP(A3,Participants!$A$2:$B$86,2,FALSE)
A4: user_0001 | B4: C1 | C4: C3 | D4: 2 | E4: 2026-03-21T10:27:13.498879+00:00 | F4: 2026-03-21T10:27:13.520056+00:00 | G4: 8 | H4: 177.94 | I4: 2 | J4: 1 | K4: 1 | M4: matches_completely | N4: 3 | Q4: correct | R4: correct | S4: matches_completely | T4: correct | U4: =IF(T4="correct",1,0) | V4: =VLOOKUP(A4,Participants!$A$2:$B$86,2,FALSE)
A5: user_0001 | B5: S2 | C5: C1 | D5: 3 | E5: 2026-03-21T10:36:38.264817+00:00 | F5: 2026-03-21T10:36:38.282641+00:00 | G5: 4 | H5: 75.88 | I5: 1 | J5: 1 | K5: 1 | M5: matches_completely | N5: 4 | Q5: correct | R5: correct | S5: matches_completely | T5: correct | U5: =IF(T5="correct",1,0) | V5: =VLOOKUP(A5,Participants!$A$2:$B$86,2,FALSE)
A6: user_0001 | B6: M2 | C6: C2 | D6: 4 | E6: 2026-03-21T10:39:36.228744+00:00 | F6: 2026-03-21T10:39:36.246336+00:00 | G6: 4 | H6: 108.95 | I6: 1 | J6: 1 | K6: 1 | M6: partially | N6: 3 | Q6: correct | R6: correct | S6: partially | T6: correct | U6: =IF(T6="correct",1,0) | V6: =VLOOKUP(A6,Participants!$A$2:$B$86,2,FALSE)
A7: user_0001 | B7: C2 | C7: C3 | D7: 5 | E7: 2026-03-21T10:41:08.515339+00:00 | F7: 2026-03-21T10:41:08.536375+00:00 | G7: 4 | H7: 60.61 | I7: 1 | J7: 1 | K7: 1 | M7: matches_completely | N7: 3 | Q7: correct | R7: correct | S7: matches_completely | T7: correct | U7: =IF(T7="correct",1,0) | V7: =VLOOKUP(A7,Participants!$A$2:$B$86,2,FALSE)
A8: user_0002 | B8: S1 | C8: C1 | D8: 0 | E8: 2026-03-21T10:10:36.470477+00:00 | F8: 2026-03-21T10:10:36.490526+00:00 | G8: 7 | H8: 403.81 | I8: 2 | J8: 1 | K8: 1 | M8: matches_completely | N8: 4 | Q8: correct | R8: correct | S8: matches_completely | T8: correct | U8: =IF(T8="correct",1,0) | V8: =VLOOKUP(A8,Participants!$A$2:$B$86,2,FALSE)
A9: user_0002 | B9: M1 | C9: C2 | D9: 1 | E9: 2026-03-21T10:19:13.710421+00:00 | F9: 2026-03-21T10:19:13.731503+00:00 | G9: 10 | H9: 227.27 | I9: 3 | J9: 1 | K9: 1 | M9: partially | N9: 4 | Q9: correct | R9: correct | S9: matches_completely | T9: correct | U9: =IF(T9="correct",1,0) | V9: =VLOOKUP(A9,Participants!$A$2:$B$86,2,FALSE)
A10: user_0002 | B10: C1 | C10: C3 | D10: 2 | E10: 2026-03-21T10:23:45.323203+00:00 | F10: 2026-03-21T10:23:45.345426+00:00 | G10: 7 | H10: 160.45 | I10: 2 | J10: 1 | K10: 1 | M10: matches_completely | N10: 4 | Q10: correct | R10: correct | S10: matches_completely | T10: correct | U10: =IF(T10="correct",1,0) | V10: =VLOOKUP(A10,Participants!$A$2:$B$86,2,FALSE)
A11: user_0002 | B11: S2 | C11: C1 | D11: 3 | E11: 2026-03-21T10:31:30.940065+00:00 | F11: 2026-03-21T10:31:30.958198+00:00 | G11: 4 | H11: 67.16 | I11: 1 | J11: 1 | K11: 1 | M11: matches_completely | N11: 4 | Q11: correct | R11: correct | S11: matches_completely | T11: correct | U11: =IF(T11="correct",1,0) | V11: =VLOOKUP(A11,Participants!$A$2:$B$86,2,FALSE)
A12: user_0002 | B12: M2 | C12: C2 | D12: 4 | E12: 2026-03-21T10:35:09.901181+00:00 | F12: 2026-03-21T10:35:09.918120+00:00 | G12: 4 | H12: 171.53 | I12: 1 | J12: 1 | K12: 1 | M12: partially | N12: 4 | Q12: correct | R12: correct | S12: partially | T12: correct | U12: =IF(T12="correct",1,0) | V12: =VLOOKUP(A12,Participants!$A$2:$B$86,2,FALSE)
A13: user_0002 | B13: C2 | C13: C3 | D13: 5 | E13: 2026-03-21T10:36:39.998118+00:00 | F13: 2026-03-21T10:36:40.017811+00:00 | G13: 4 | H13: 74.95 | I13: 1 | J13: 1 | K13: 1 | M13: matches_completely | N13: 4 | Q13: correct | R13: correct | S13: matches_completely | T13: correct | U13: =IF(T13="correct",1,0) | V13: =VLOOKUP(A13,Participants!$A$2:$B$86,2,FALSE)
... A49: user_0008 | B49: C2 | C49: C3 | D49: 5 | E49: 2026-03-21T10:24:53.524622+00:00 | F49: 2026-03-21T10:24:53.541234+00:00 | G49: 4 | H49: 68.09 | I49: 1 | J49: 1 | K49: 0 | M49: matches_completely | N49: 3 | Q49: correct | R49: correct | S49: matches_completely | T49: correct | U49: =IF(T49="correct",1,0) | V49: =VLOOKUP(A49,Participants!$A$2:$B$86,2,FALSE)
A50: user_0009 | B50: S1 | C50: C1 | D50: 0 | E50: 2026-03-21T10:05:35.994453+00:00 | F50: 2026-03-21T10:05:36.012834+00:00 | G50: 7 | H50: 55.22 | I50: 2 | J50: 1 | K50: 1 | M50: partially | N50: 5 | Q50: correct | R50: correct | T50: correct | U50: =IF(T50="correct",1,0) | V50: =VLOOKUP(A50,Participants!$A$2:$B$86,2,FALSE)
A51: user_0009 | B51: M1 | C51: C2 | D51: 1 | E51: 2026-03-21T10:10:28.654919+00:00 | F51: 2026-03-21T10:10:28.681730+00:00 | G51: 12 | H51: 61.11 | I51: 2 | J51: 1 | K51: 1 | M51: partially | N51: 4 | Q51: correct | R51: correct | T51: correct | U51: =IF(T51="correct",1,0) | V51: =VLOOKUP(A51,Participants!$A$2:$B$86,2,FALSE)
A52: user_0009 | B52: C1 | C52: C3 | D52: 2 | E52: 2026-03-21T10:14:15.898192+00:00 | F52: 2026-03-21T10:14:15.916821+00:00 | G52: 7 | H52: 196.97 | I52: 2 | J52: 1 | K52: 1 | M52: partially | N52: 5 | Q52: correct | R52: correct | T52: correct | U52: =IF(T52="correct",1,0) | V52: =VLOOKUP(A52,Participants!$A$2:$B$86,2,FALSE)
A53: user_0009 | B53: S2 | C53: C1 | D53: 3 | E53: 2026-03-21T10:20:14.628663+00:00 | F53: 2026-03-21T10:20:14.649350+00:00 | G53: 4 | H53: 118.7 | I53: 1 | J53: 1 | K53: 1 | M53: matches_completely | N53: 5 | Q53: correct | R53: correct | T53: correct | U53: =IF(T53="correct",1,0) | V53: =VLOOKUP(A53,Participants!$A$2:$B$86,2,FALSE)
A54: user_0009 | B54: M2 | C54: C2 | D54: 4 | E54: 2026-03-21T10:21:53.378159+00:00 | F54: 2026-03-21T10:21:53.403437+00:00 | G54: 4 | H54: 106.08 | I54: 1 | J54: 1 | K54: 1 | M54: partially | N54: 4 | Q54: correct | R54: correct | T54: correct | U54: =IF(T54="correct",1,0) | V54: =VLOOKUP(A54,Participants!$A$2:$B$86,2,FALSE)
A55: user_0009 | B55: C2 | C55: C3 | D55: 5 | E55: 2026-03-21T10:27:00.311975+00:00 | F55: 2026-03-21T10:27:00.332777+00:00 | G55: 4 | H55: 181.42 | I55: 1 | J55: 1 | K55: 1 | M55: partially | N55: 4 | Q55: correct | R55: correct | T55: correct | U55: =IF(T55="correct",1,0) | V55: =VLOOKUP(A55,Participants!$A$2:$B$86,2,FALSE)
A56: user_0010 | B56: S1 | C56: C1 | D56: 0 | E56: 2026-03-21T10:05:03.006480+00:00 | F56: 2026-03-21T10:05:03.029907+00:00 | G56: 10 | H56: 88.56 | I56: 3 | J56: 1 | K56: 1 | M56: partially | N56: 4 | Q56: correct | R56: correct | S56: matches_completely | T56: correct | U56: =IF(T56="correct",1,0) | V56: =VLOOKUP(A56,Participants!$A$2:$B$86,2,FALSE)
A57: user_0010 | B57: M1 | C57: C2 | D57: 1 | E57: 2026-03-21T10:08:44.431850+00:00 | F57: 2026-03-21T10:08:44.452312+00:00 | G57: 7 | H57: 41.62 | I57: 2 | J57: 1 | K57: 1 | M57: matches_completely | N57: 5 | Q57: correct | R57: correct | S57: matches_completely | T57: correct | U57: =IF(T57="correct",1,0) | V57: =VLOOKUP(A57,Participants!$A$2:$B$86,2,FALSE)
A58: user_0010 | B58: C1 | C58: C3 | D58: 2 | E58: 2026-03-21T10:11:13.331837+00:00 | F58: 2026-03-21T10:11:13.347470+00:00 | G58: 7 | H58: 149.05 | I58: 2 | J58: 1 | K58: 1 | M58: matches_completely | N58: 5 | Q58: correct | R58: correct | S58: matches_completely | T58: correct | U58: =IF(T58="correct",1,0) | V58: =VLOOKUP(A58,Participants!$A$2:$B$86,2,FALSE)
A59: user_0010 | B59: S2 | C59: C1 | D59: 3 | E59: 2026-03-21T10:15:55.626848+00:00 | F59: 2026-03-21T10:15:55.644442+00:00 | G59: 10 | H59: 219.64 | I59: 3 | J59: 1 | K59: 1 | M59: matches_completely | N59: 5 | Q59: correct | R59: correct | S59: matches_completely | T59: correct | U59: =IF(T59="correct",1,0) | V59: =VLOOKUP(A59,Participants!$A$2:$B$86,2,FALSE)
A60: user_0010 | B60: M2 | C60: C2 | D60: 4 | E60: 2026-03-21T10:17:04.162943+00:00 | F60: 2026-03-21T10:17:04.183456+00:00 | G60: 7 | H60: 101.23 | I60: 2 | J60: 1 | K60: 1 | M60: matches_completely | N60: 5 | Q60: correct | R60: correct | S60: does_not_match | T60: correct | U60: =IF(T60="correct",1,0) | V60: =VLOOKUP(A60,Participants!$A$2:$B$86,2,FALSE)
A61: user_0010 | B61: C2 | C61: C3 | D61: 5 | E61: 2026-03-21T10:19:57.959919+00:00 | F61: 2026-03-21T10:19:57.980753+00:00 | G61: 4 | H61: 197.38 | I61: 1 | J61: 1 | K61: 1 | M61: matches_completely | N61: 3 | Q61: correct | R61: correct | S61: matches_completely | T61: correct | U61: =IF(T61="correct",1,0) | V61: =VLOOKUP(A61,Participants!$A$2:$B$86,2,FALSE)
A62: user_0011 | B62: S1 | C62: C1 | D62: 0 | E62: 2026-03-21T10:07:38.768049+00:00 | F62: 2026-03-21T10:07:38.786029+00:00 | G62: 9 | H62: 290.95 | I62: 3 | J62: 1 | K62: 1 | M62: matches_completely | N62: 4 | Q62: correct | R62: correct | S62: matches_completely | T62: correct | U62: =IF(T62="correct",1,0) | V62: =VLOOKUP(A62,Participants!$A$2:$B$86,2,FALSE)
A63: user_0011 | B63: M1 | C63: C2 | D63: 1 | E63: 2026-03-21T10:12:52.368991+00:00 | F63: 2026-03-21T10:12:52.385558+00:00 | G63: 13 | H63: 115.02 | I63: 3 | J63: 1 | K63: 1 | M63: partially | N63: 4 | Q63: correct | R63: correct | S63: matches_completely | T63: correct | U63: =IF(T63="correct",1,0) | V63: =VLOOKUP(A63,Participants!$A$2:$B$86,2,FALSE)
A64: user_0011 | B64: C1 | C64: C3 | D64: 2 | E64: 2026-03-21T10:17:53.735421+00:00 | F64: 2026-03-21T10:17:53.755078+00:00 | G64: 9 | H64: 280.25 | I64: 2 | J64: 1 | K64: 1 | M64: matches_completely | N64: 4 | Q64: correct | R64: correct | S64: matches_completely | T64: correct | U64: =IF(T64="correct",1,0) | V64: =VLOOKUP(A64,Participants!$A$2:$B$86,2,FALSE)
A65: user_0011 | B65: S2 | C65: C1 | D65: 3 | E65: 2026-03-21T10:25:02.804953+00:00 | F65: 2026-03-21T10:25:02.831414+00:00 | G65: 9 | H65: 162.94 | I65: 2 | J65: 1 | K65: 1 | M65: matches_completely | N65: 5 | Q65: correct | R65: correct | S65: does_not_match | T65: correct | U65: =IF(T65="correct",1,0) | V65: =VLOOKUP(A65,Participants!$A$2:$B$86,2,FALSE)
A66: user_0011 | B66: M2 | C66: C2 | D66: 4 | E66: 2026-03-21T10:27:55.347454+00:00 | F66: 2026-03-21T10:27:55.365683+00:00 | G66: 7 | H66: 129.78 | I66: 2 | J66: 1 | K66: 1 | M66: partially | N66: 4 | Q66: correct | R66: correct | S66: partially | T66: correct | U66: =IF(T66="correct",1,0) | V66: =VLOOKUP(A66,Participants!$A$2:$B$86,2,FALSE)
A67: user_0011 | B67: C2 | C67: C3 | D67: 5 | E67: 2026-03-21T10:31:23.722664+00:00 | F67: 2026-03-21T10:31:23.741069+00:00 | G67: 10 | H67: 204.56 | I67: 3 | J67: 1 | K67: 0 | M67: partially | N67: 3 | Q67: correct | R67: correct | S67: matches_completely | T67: correct | U67: =IF(T67="correct",1,0) | V67: =VLOOKUP(A67,Participants!$A$2:$B$86,2,FALSE)
... A73: user_0013 | B73: C2 | C73: C3 | D73: 5 | E73: 2026-03-21T10:24:26.057059+00:00 | F73: 2026-03-21T10:24:26.074420+00:00 | G73: 4 | H73: 122.23 | I73: 1 | J73: 1 | K73: 1 | M73: partially | N73: 3 | Q73: correct | R73: correct | S73: matches_completely | T73: correct | U73: =IF(T73="correct",1,0) | V73: =VLOOKUP(A73,Participants!$A$2:$B$86,2,FALSE)
A74: user_0015 | B74: S1 | C74: C1 | D74: 0 | E74: 2026-03-21T10:07:53.806355+00:00 | F74: 2026-03-21T10:07:53.823584+00:00 | G74: 4 | H74: 172.16 | I74: 1 | J74: 1 | K74: 1 | M74: matches_completely | N74: 5 | Q74: correct | R74: correct | T74: correct | U74: =IF(T74="correct",1,0) | V74: =VLOOKUP(A74,Participants!$A$2:$B$86,2,FALSE)
A75: user_0015 | B75: M1 | C75: C2 | D75: 1 | E75: 2026-03-21T10:18:16.512088+00:00 | F75: 2026-03-21T10:18:16.533255+00:00 | G75: 8 | H75: 128.08 | I75: 2 | J75: 1 | K75: 1 | M75: matches_completely | N75: 3 | Q75: correct | R75: correct | T75: correct | U75: =IF(T75="correct",1,0) | V75: =VLOOKUP(A75,Participants!$A$2:$B$86,2,FALSE)
A76: user_0015 | B76: C1 | C76: C3 | D76: 2 | E76: 2026-03-21T10:20:11.404549+00:00 | F76: 2026-03-21T10:20:11.422805+00:00 | G76: 4 | H76: 65.69 | I76: 1 | J76: 1 | K76: 1 | M76: matches_completely | N76: 3 | Q76: correct | R76: correct | T76: correct | U76: =IF(T76="correct",1,0) | V76: =VLOOKUP(A76,Participants!$A$2:$B$86,2,FALSE)
A77: user_0015 | B77: S2 | C77: C1 | D77: 3 | E77: 2026-03-21T10:28:32.778128+00:00 | F77: 2026-03-21T10:28:32.799727+00:00 | G77: 4 | H77: 102.38 | I77: 1 | J77: 1 | K77: 1 | M77: matches_completely | N77: 5 | Q77: correct | R77: correct | T77: correct | U77: =IF(T77="correct",1,0) | V77: =VLOOKUP(A77,Participants!$A$2:$B$86,2,FALSE)
A78: user_0015 | B78: M2 | C78: C2 | D78: 4 | E78: 2026-03-21T10:35:03.784059+00:00 | F78: 2026-03-21T10:35:03.805173+00:00 | G78: 10 | H78: 313.91 | I78: 3 | J78: 1 | K78: 1 | M78: matches_completely | N78: 3 | Q78: correct | R78: correct | T78: correct | U78: =IF(T78="correct",1,0) | V78: =VLOOKUP(A78,Participants!$A$2:$B$86,2,FALSE)
A79: user_0015 | B79: C2 | C79: C3 | D79: 5 | E79: 2026-03-21T10:37:58.213135+00:00 | F79: 2026-03-21T10:37:58.231135+00:00 | G79: 7 | H79: 153.78 | I79: 2 | J79: 1 | K79: 1 | M79: matches_completely | N79: 5 | Q79: correct | R79: correct | T79: correct | U79: =IF(T79="correct",1,0) | V79: =VLOOKUP(A79,Participants!$A$2:$B$86,2,FALSE)
A80: user_0016 | B80: S1 | C80: C1 | D80: 0 | E80: 2026-03-21T10:10:39.200352+00:00 | F80: 2026-03-21T10:10:39.220946+00:00 | G80: 11 | H80: 469.47 | I80: 3 | J80: 1 | K80: 1 | M80: partially | N80: 3 | Q80: correct | R80: correct | S80: matches_completely | T80: correct | U80: =IF(T80="correct",1,0) | V80: =VLOOKUP(A80,Participants!$A$2:$B$86,2,FALSE)
...

Sheet PerParticipant
A1: participant_id | B1: user_type | C1: sus_score | D1: tlx_overall | E1: tlx_mental | F1: tlx_temporal | G1: tlx_performance | H1: tlx_effort | I1: tlx_frustration | J1: toast_understanding | K1: toast_performance | L1: toast_overall | M1: avg_time_s | N1: success_rate | O1: avg_attempts | P1: rank_sus | Q1: rank_tlx | R1: rank_toast | S1: rank_time
A2: user_0001 | B2: =VLOOKUP(A2,Participants!$A$2:$B$86,2,FALSE) | C2: =AVERAGEIFS(SUS!$W$2:$W$86,SUS!$A$2:$A$86,A2) | D2: =AVERAGEIFS(TLX!$H$2:$H$86,TLX!$A$2:$A$86,A2) | E2: =AVERAGEIFS(TLX!$B$2:$B$86,TLX!$A$2:$A$86,A2) | F2: =AVERAGEIFS(TLX!$D$2:$D$86,TLX!$A$2:$A$86,A2) | G2: =AVERAGEIFS(TLX!$E$2:$E$86,TLX!$A$2:$A$86,A2) | H2: =AVERAGEIFS(TLX!$F$2:$F$86,TLX!$A$2:$A$86,A2) | I2: =AVERAGEIFS(TLX!$G$2:$G$86,TLX!$A$2:$A$86,A2) | J2: =IFERROR(AVERAGEIFS(TOAST!$K$2:$K$86,TOAST!$A$2:$A$86,A2),NA()) | K2: =IFERROR(AVERAGEIFS(TOAST!$L$2:$L$86,TOAST!$A$2:$A$86,A2),NA()) | L2: =IFERROR(AVERAGEIFS(TOAST!$M$2:$M$86,TOAST!$A$2:$A$86,A2),NA()) | M2: =AVERAGEIFS(Sessions!$H$2:$H$511,Sessions!$A$2:$A$511,A2) | N2: =AVERAGEIFS(Sessions!$U$2:$U$511,Sessions!$A$2:$A$511,A2) | O2: =AVERAGEIFS(Sessions!$I$2:$I$511,Sessions!$A$2:$A$511,A2) | P2: =_xlfn.RANK.AVG(C2,$C$2:$C$86,1) | Q2: =_xlfn.RANK.AVG(D2,$D$2:$D$86,1) | R2: =_xlfn.RANK.AVG(L2,$L$2:$L$86,1) | S2: =_xlfn.RANK.AVG(M2,$M$2:$M$86,1)
A3: user_0002 | B3: =VLOOKUP(A3,Participants!$A$2:$B$86,2,FALSE) | C3: =AVERAGEIFS(SUS!$W$2:$W$86,SUS!$A$2:$A$86,A3) | D3: =AVERAGEIFS(TLX!$H$2:$H$86,TLX!$A$2:$A$86,A3) | E3: =AVERAGEIFS(TLX!$B$2:$B$86,TLX!$A$2:$A$86,A3) | F3: =AVERAGEIFS(TLX!$D$2:$D$86,TLX!$A$2:$A$86,A3) | G3: =AVERAGEIFS(TLX!$E$2:$E$86,TLX!$A$2:$A$86,A3) | H3: =AVERAGEIFS(TLX!$F$2:$F$86,TLX!$A$2:$A$86,A3) | I3: =AVERAGEIFS(TLX!$G$2:$G$86,TLX!$A$2:$A$86,A3) | J3: =IFERROR(AVERAGEIFS(TOAST!$K$2:$K$86,TOAST!$A$2:$A$86,A3),NA()) | K3: =IFERROR(AVERAGEIFS(TOAST!$L$2:$L$86,TOAST!$A$2:$A$86,A3),NA()) | L3: =IFERROR(AVERAGEIFS(TOAST!$M$2:$M$86,TOAST!$A$2:$A$86,A3),NA()) | M3: =AVERAGEIFS(Sessions!$H$2:$H$511,Sessions!$A$2:$A$511,A3) | N3: =AVERAGEIFS(Sessions!$U$2:$U$511,Sessions!$A$2:$A$511,A3) | O3: =AVERAGEIFS(Sessions!$I$2:$I$511,Sessions!$A$2:$A$511,A3) | P3: =_xlfn.RANK.AVG(C3,$C$2:$C$86,1) | Q3: =_xlfn.RANK.AVG(D3,$D$2:$D$86,1) | R3: =_xlfn.RANK.AVG(L3,$L$2:$L$86,1) | S3: =_xlfn.RANK.AVG(M3,$M$2:$M$86,1)
A4: user_0003 | B4: =VLOOKUP(A4,Participants!$A$2:$B$86,2,FALSE) | C4: =AVERAGEIFS(SUS!$W$2:$W$86,SUS!$A$2:$A$86,A4) | D4: =AVERAGEIFS(TLX!$H$2:$H$86,TLX!$A$2:$A$86,A4) | E4: =AVERAGEIFS(TLX!$B$2:$B$86,TLX!$A$2:$A$86,A4) | F4: =AVERAGEIFS(TLX!$D$2:$D$86,TLX!$A$2:$A$86,A4) | G4: =AVERAGEIFS(TLX!$E$2:$E$86,TLX!$A$2:$A$86,A4) | H4: =AVERAGEIFS(TLX!$F$2:$F$86,TLX!$A$2:$A$86,A4) | I4: =AVERAGEIFS(TLX!$G$2:$G$86,TLX!$A$2:$A$86,A4) | J4: =IFERROR(AVERAGEIFS(TOAST!$K$2:$K$86,TOAST!$A$2:$A$86,A4),NA()) | K4: =IFERROR(AVERAGEIFS(TOAST!$L$2:$L$86,TOAST!$A$2:$A$86,A4),NA()) | L4: =IFERROR(AVERAGEIFS(TOAST!$M$2:$M$86,TOAST!$A$2:$A$86,A4),NA()) | M4: =AVERAGEIFS(Sessions!$H$2:$H$511,Sessions!$A$2:$A$511,A4) | N4: =AVERAGEIFS(Sessions!$U$2:$U$511,Sessions!$A$2:$A$511,A4) | O4: =AVERAGEIFS(Sessions!$I$2:$I$511,Sessions!$A$2:$A$511,A4) | P4: =_xlfn.RANK.AVG(C4,$C$2:$C$86,1) | Q4: =_xlfn.RANK.AVG(D4,$D$2:$D$86,1) | R4: =_xlfn.RANK.AVG(L4,$L$2:$L$86,1) | S4: =_xlfn.RANK.AVG(M4,$M$2:$M$86,1)
A5: user_0004 | B5: =VLOOKUP(A5,Participants!$A$2:$B$86,2,FALSE) | C5: =AVERAGEIFS(SUS!$W$2:$W$86,SUS!$A$2:$A$86,A5) | D5: =AVERAGEIFS(TLX!$H$2:$H$86,TLX!$A$2:$A$86,A5) | E5: =AVERAGEIFS(TLX!$B$2:$B$86,TLX!$A$2:$A$86,A5) | F5: =AVERAGEIFS(TLX!$D$2:$D$86,TLX!$A$2:$A$86,A5) | G5: =AVERAGEIFS(TLX!$E$2:$E$86,TLX!$A$2:$A$86,A5) | H5: =AVERAGEIFS(TLX!$F$2:$F$86,TLX!$A$2:$A$86,A5) | I5: =AVERAGEIFS(TLX!$G$2:$G$86,TLX!$A$2:$A$86,A5) | J5: =IFERROR(AVERAGEIFS(TOAST!$K$2:$K$86,TOAST!$A$2:$A$86,A5),NA()) | K5: =IFERROR(AVERAGEIFS(TOAST!$L$2:$L$86,TOAST!$A$2:$A$86,A5),NA()) | L5: =IFERROR(AVERAGEIFS(TOAST!$M$2:$M$86,TOAST!$A$2:$A$86,A5),NA()) | M5: =AVERAGEIFS(Sessions!$H$2:$H$511,Sessions!$A$2:$A$511,A5) | N5: =AVERAGEIFS(Sessions!$U$2:$U$511,Sessions!$A$2:$A$511,A5) | O5: =AVERAGEIFS(Sessions!$I$2:$I$511,Sessions!$A$2:$A$511,A5) | P5: =_xlfn.RANK.AVG(C5,$C$2:$C$86,1) | Q5: =_xlfn.RANK.AVG(D5,$D$2:$D$86,1) | R5: =_xlfn.RANK.AVG(L5,$L$2:$L$86,1) | S5: =_xlfn.RANK.AVG(M5,$M$2:$M$86,1)
A6: user_0005 | B6: =VLOOKUP(A6,Participants!$A$2:$B$86,2,FALSE) | C6: =AVERAGEIFS(SUS!$W$2:$W$86,SUS!$A$2:$A$86,A6) | D6: =AVERAGEIFS(TLX!$H$2:$H$86,TLX!$A$2:$A$86,A6) | E6: =AVERAGEIFS(TLX!$B$2:$B$86,TLX!$A$2:$A$86,A6) | F6: =AVERAGEIFS(TLX!$D$2:$D$86,TLX!$A$2:$A$86,A6) | G6: =AVERAGEIFS(TLX!$E$2:$E$86,TLX!$A$2:$A$86,A6) | H6: =AVERAGEIFS(TLX!$F$2:$F$86,TLX!$A$2:$A$86,A6) | I6: =AVERAGEIFS(TLX!$G$2:$G$86,TLX!$A$2:$A$86,A6) | J6: =IFERROR(AVERAGEIFS(TOAST!$K$2:$K$86,TOAST!$A$2:$A$86,A6),NA()) | K6: =IFERROR(AVERAGEIFS(TOAST!$L$2:$L$86,TOAST!$A$2:$A$86,A6),NA()) | L6: =IFERROR(AVERAGEIFS(TOAST!$M$2:$M$86,TOAST!$A$2:$A$86,A6),NA()) | M6: =AVERAGEIFS(Sessions!$H$2:$H$511,Sessions!$A$2:$A$511,A6) | N6: =AVERAGEIFS(Sessions!$U$2:$U$511,Sessions!$A$2:$A$511,A6) | O6: =AVERAGEIFS(Sessions!$I$2:$I$511,Sessions!$A$2:$A$511,A6) | P6: =_xlfn.RANK.AVG(C6,$C$2:$C$86,1) | Q6: =_xlfn.RANK.AVG(D6,$D$2:$D$86,1) | R6: =_xlfn.RANK.AVG(L6,$L$2:$L$86,1) | S6: =_xlfn.RANK.AVG(M6,$M$2:$M$86,1)
A7: user_0006 | B7: =VLOOKUP(A7,Participants!$A$2:$B$86,2,FALSE) | C7: =AVERAGEIFS(SUS!$W$2:$W$86,SUS!$A$2:$A$86,A7) | D7: =AVERAGEIFS(TLX!$H$2:$H$86,TLX!$A$2:$A$86,A7) | E7: =AVERAGEIFS(TLX!$B$2:$B$86,TLX!$A$2:$A$86,A7) | F7: =AVERAGEIFS(TLX!$D$2:$D$86,TLX!$A$2:$A$86,A7) | G7: =AVERAGEIFS(TLX!$E$2:$E$86,TLX!$A$2:$A$86,A7) | H7: =AVERAGEIFS(TLX!$F$2:$F$86,TLX!$A$2:$A$86,A7) | I7: =AVERAGEIFS(TLX!$G$2:$G$86,TLX!$A$2:$A$86,A7) | J7: =IFERROR(AVERAGEIFS(TOAST!$K$2:$K$86,TOAST!$A$2:$A$86,A7),NA()) | K7: =IFERROR(AVERAGEIFS(TOAST!$L$2:$L$86,TOAST!$A$2:$A$86,A7),NA()) | L7: =IFERROR(AVERAGEIFS(TOAST!$M$2:$M$86,TOAST!$A$2:$A$86,A7),NA()) | M7: =AVERAGEIFS(Sessions!$H$2:$H$511,Sessions!$A$2:$A$511,A7) | N7: =AVERAGEIFS(Sessions!$U$2:$U$511,Sessions!$A$2:$A$511,A7) | O7: =AVERAGEIFS(Sessions!$I$2:$I$511,Sessions!$A$2:$A$511,A7) | P7: =_xlfn.RANK.AVG(C7,$C$2:$C$86,1) | Q7: =_xlfn.RANK.AVG(D7,$D$2:$D$86,1) | R7: =_xlfn.RANK.AVG(L7,$L$2:$L$86,1) | S7: =_xlfn.RANK.AVG(M7,$M$2:$M$86,1)
A8: user_0007 | B8: =VLOOKUP(A8,Participants!$A$2:$B$86,2,FALSE) | C8: =AVERAGEIFS(SUS!$W$2:$W$86,SUS!$A$2:$A$86,A8) | D8: =AVERAGEIFS(TLX!$H$2:$H$86,TLX!$A$2:$A$86,A8) | E8: =AVERAGEIFS(TLX!$B$2:$B$86,TLX!$A$2:$A$86,A8) | F8: =AVERAGEIFS(TLX!$D$2:$D$86,TLX!$A$2:$A$86,A8) | G8: =AVERAGEIFS(TLX!$E$2:$E$86,TLX!$A$2:$A$86,A8) | H8: =AVERAGEIFS(TLX!$F$2:$F$86,TLX!$A$2:$A$86,A8) | I8: =AVERAGEIFS(TLX!$G$2:$G$86,TLX!$A$2:$A$86,A8) | J8: =IFERROR(AVERAGEIFS(TOAST!$K$2:$K$86,TOAST!$A$2:$A$86,A8),NA()) | K8: =IFERROR(AVERAGEIFS(TOAST!$L$2:$L$86,TOAST!$A$2:$A$86,A8),NA()) | L8: =IFERROR(AVERAGEIFS(TOAST!$M$2:$M$86,TOAST!$A$2:$A$86,A8),NA()) | M8: =AVERAGEIFS(Sessions!$H$2:$H$511,Sessions!$A$2:$A$511,A8) | N8: =AVERAGEIFS(Sessions!$U$2:$U$511,Sessions!$A$2:$A$511,A8) | O8: =AVERAGEIFS(Sessions!$I$2:$I$511,Sessions!$A$2:$A$511,A8) | P8: =_xlfn.RANK.AVG(C8,$C$2:$C$86,1) | Q8: =_xlfn.RANK.AVG(D8,$D$2:$D$86,1) | R8: =_xlfn.RANK.AVG(L8,$L$2:$L$86,1) | S8: =_xlfn.RANK.AVG(M8,$M$2:$M$86,1)
A9: user_0008 | B9: =VLOOKUP(A9,Participants!$A$2:$B$86,2,FALSE) | C9: =AVERAGEIFS(SUS!$W$2:$W$86,SUS!$A$2:$A$86,A9) | D9: =AVERAGEIFS(TLX!$H$2:$H$86,TLX!$A$2:$A$86,A9) | E9: =AVERAGEIFS(TLX!$B$2:$B$86,TLX!$A$2:$A$86,A9) | F9: =AVERAGEIFS(TLX!$D$2:$D$86,TLX!$A$2:$A$86,A9) | G9: =AVERAGEIFS(TLX!$E$2:$E$86,TLX!$A$2:$A$86,A9) | H9: =AVERAGEIFS(TLX!$F$2:$F$86,TLX!$A$2:$A$86,A9) | I9: =AVERAGEIFS(TLX!$G$2:$G$86,TLX!$A$2:$A$86,A9) | J9: =IFERROR(AVERAGEIFS(TOAST!$K$2:$K$86,TOAST!$A$2:$A$86,A9),NA()) | K9: =IFERROR(AVERAGEIFS(TOAST!$L$2:$L$86,TOAST!$A$2:$A$86,A9),NA()) | L9: =IFERROR(AVERAGEIFS(TOAST!$M$2:$M$86,TOAST!$A$2:$A$86,A9),NA()) | M9: =AVERAGEIFS(Sessions!$H$2:$H$511,Sessions!$A$2:$A$511,A9) | N9: =AVERAGEIFS(Sessions!$U$2:$U$511,Sessions!$A$2:$A$511,A9) | O9: =AVERAGEIFS(Sessions!$I$2:$I$511,Sessions!$A$2:$A$511,A9) | P9: =_xlfn.RANK.AVG(C9,$C$2:$C$86,1) | Q9: =_xlfn.RANK.AVG(D9,$D$2:$D$86,1) | R9: =_xlfn.RANK.AVG(L9,$L$2:$L$86,1) | S9: =_xlfn.RANK.AVG(M9,$M$2:$M$86,1)
A10: user_0009 | B10: =VLOOKUP(A10,Participants!$A$2:$B$86,2,FALSE) | C10: =AVERAGEIFS(SUS!$W$2:$W$86,SUS!$A$2:$A$86,A10) | D10: =AVERAGEIFS(TLX!$H$2:$H$86,TLX!$A$2:$A$86,A10) | E10: =AVERAGEIFS(TLX!$B$2:$B$86,TLX!$A$2:$A$86,A10) | F10: =AVERAGEIFS(TLX!$D$2:$D$86,TLX!$A$2:$A$86,A10) | G10: =AVERAGEIFS(TLX!$E$2:$E$86,TLX!$A$2:$A$86,A10) | H10: =AVERAGEIFS(TLX!$F$2:$F$86,TLX!$A$2:$A$86,A10) | I10: =AVERAGEIFS(TLX!$G$2:$G$86,TLX!$A$2:$A$86,A10) | J10: =IFERROR(AVERAGEIFS(TOAST!$K$2:$K$86,TOAST!$A$2:$A$86,A10),NA()) | K10: =IFERROR(AVERAGEIFS(TOAST!$L$2:$L$86,TOAST!$A$2:$A$86,A10),NA()) | L10: =IFERROR(AVERAGEIFS(TOAST!$M$2:$M$86,TOAST!$A$2:$A$86,A10),NA()) | M10: =AVERAGEIFS(Sessions!$H$2:$H$511,Sessions!$A$2:$A$511,A10) | N10: =AVERAGEIFS(Sessions!$U$2:$U$511,Sessions!$A$2:$A$511,A10) | O10: =AVERAGEIFS(Sessions!$I$2:$I$511,Sessions!$A$2:$A$511,A10) | P10: =_xlfn.RANK.AVG(C10,$C$2:$C$86,1) | Q10: =_xlfn.RANK.AVG(D10,$D$2:$D$86,1) | R10: =_xlfn.RANK.AVG(L10,$L$2:$L$86,1) | S10: =_xlfn.RANK.AVG(M10,$M$2:$M$86,1)
A11: user_0010 | B11: =VLOOKUP(A11,Participants!$A$2:$B$86,2,FALSE) | C11: =AVERAGEIFS(SUS!$W$2:$W$86,SUS!$A$2:$A$86,A11) | D11: =AVERAGEIFS(TLX!$H$2:$H$86,TLX!$A$2:$A$86,A11) | E11: =AVERAGEIFS(TLX!$B$2:$B$86,TLX!$A$2:$A$86,A11) | F11: =AVERAGEIFS(TLX!$D$2:$D$86,TLX!$A$2:$A$86,A11) | G11: =AVERAGEIFS(TLX!$E$2:$E$86,TLX!$A$2:$A$86,A11) | H11: =AVERAGEIFS(TLX!$F$2:$F$86,TLX!$A$2:$A$86,A11) | I11: =AVERAGEIFS(TLX!$G$2:$G$86,TLX!$A$2:$A$86,A11) | J11: =IFERROR(AVERAGEIFS(TOAST!$K$2:$K$86,TOAST!$A$2:$A$86,A11),NA()) | K11: =IFERROR(AVERAGEIFS(TOAST!$L$2:$L$86,TOAST!$A$2:$A$86,A11),NA()) | L11: =IFERROR(AVERAGEIFS(TOAST!$M$2:$M$86,TOAST!$A$2:$A$86,A11),NA()) | M11: =AVERAGEIFS(Sessions!$H$2:$H$511,Sessions!$A$2:$A$511,A11) | N11: =AVERAGEIFS(Sessions!$U$2:$U$511,Sessions!$A$2:$A$511,A11) | O11: =AVERAGEIFS(Sessions!$I$2:$I$511,Sessions!$A$2:$A$511,A11) | P11: =_xlfn.RANK.AVG(C11,$C$2:$C$86,1) | Q11: =_xlfn.RANK.AVG(D11,$D$2:$D$86,1) | R11: =_xlfn.RANK.AVG(L11,$L$2:$L$86,1) | S11: =_xlfn.RANK.AVG(M11,$M$2:$M$86,1)
A12: user_0011 | B12: =VLOOKUP(A12,Participants!$A$2:$B$86,2,FALSE) | C12: =AVERAGEIFS(SUS!$W$2:$W$86,SUS!$A$2:$A$86,A12) | D12: =AVERAGEIFS(TLX!$H$2:$H$86,TLX!$A$2:$A$86,A12) | E12: =AVERAGEIFS(TLX!$B$2:$B$86,TLX!$A$2:$A$86,A12) | F12: =AVERAGEIFS(TLX!$D$2:$D$86,TLX!$A$2:$A$86,A12) | G12: =AVERAGEIFS(TLX!$E$2:$E$86,TLX!$A$2:$A$86,A12) | H12: =AVERAGEIFS(TLX!$F$2:$F$86,TLX!$A$2:$A$86,A12) | I12: =AVERAGEIFS(TLX!$G$2:$G$86,TLX!$A$2:$A$86,A12) | J12: =IFERROR(AVERAGEIFS(TOAST!$K$2:$K$86,TOAST!$A$2:$A$86,A12),NA()) | K12: =IFERROR(AVERAGEIFS(TOAST!$L$2:$L$86,TOAST!$A$2:$A$86,A12),NA()) | L12: =IFERROR(AVERAGEIFS(TOAST!$M$2:$M$86,TOAST!$A$2:$A$86,A12),NA()) | M12: =AVERAGEIFS(Sessions!$H$2:$H$511,Sessions!$A$2:$A$511,A12) | N12: =AVERAGEIFS(Sessions!$U$2:$U$511,Sessions!$A$2:$A$511,A12) | O12: =AVERAGEIFS(Sessions!$I$2:$I$511,Sessions!$A$2:$A$511,A12) | P12: =_xlfn.RANK.AVG(C12,$C$2:$C$86,1) | Q12: =_xlfn.RANK.AVG(D12,$D$2:$D$86,1) | R12: =_xlfn.RANK.AVG(L12,$L$2:$L$86,1) | S12: =_xlfn.RANK.AVG(M12,$M$2:$M$86,1)
A13: user_0013 | B13: =VLOOKUP(A13,Participants!$A$2:$B$86,2,FALSE) | C13: =AVERAGEIFS(SUS!$W$2:$W$86,SUS!$A$2:$A$86,A13) | D13: =AVERAGEIFS(TLX!$H$2:$H$86,TLX!$A$2:$A$86,A13) | E13: =AVERAGEIFS(TLX!$B$2:$B$86,TLX!$A$2:$A$86,A13) | F13: =AVERAGEIFS(TLX!$D$2:$D$86,TLX!$A$2:$A$86,A13) | G13: =AVERAGEIFS(TLX!$E$2:$E$86,TLX!$A$2:$A$86,A13) | H13: =AVERAGEIFS(TLX!$F$2:$F$86,TLX!$A$2:$A$86,A13) | I13: =AVERAGEIFS(TLX!$G$2:$G$86,TLX!$A$2:$A$86,A13) | J13: =IFERROR(AVERAGEIFS(TOAST!$K$2:$K$86,TOAST!$A$2:$A$86,A13),NA()) | K13: =IFERROR(AVERAGEIFS(TOAST!$L$2:$L$86,TOAST!$A$2:$A$86,A13),NA()) | L13: =IFERROR(AVERAGEIFS(TOAST!$M$2:$M$86,TOAST!$A$2:$A$86,A13),NA()) | M13: =AVERAGEIFS(Sessions!$H$2:$H$511,Sessions!$A$2:$A$511,A13) | N13: =AVERAGEIFS(Sessions!$U$2:$U$511,Sessions!$A$2:$A$511,A13) | O13: =AVERAGEIFS(Sessions!$I$2:$I$511,Sessions!$A$2:$A$511,A13) | P13: =_xlfn.RANK.AVG(C13,$C$2:$C$86,1) | Q13: =_xlfn.RANK.AVG(D13,$D$2:$D$86,1) | R13: =_xlfn.RANK.AVG(L13,$L$2:$L$86,1) | S13: =_xlfn.RANK.AVG(M13,$M$2:$M$86,1)
... A86: user_0205 | B86: =VLOOKUP(A86,Participants!$A$2:$B$86,2,FALSE) | C86: =AVERAGEIFS(SUS!$W$2:$W$86,SUS!$A$2:$A$86,A86) | D86: =AVERAGEIFS(TLX!$H$2:$H$86,TLX!$A$2:$A$86,A86) | E86: =AVERAGEIFS(TLX!$B$2:$B$86,TLX!$A$2:$A$86,A86) | F86: =AVERAGEIFS(TLX!$D$2:$D$86,TLX!$A$2:$A$86,A86) | G86: =AVERAGEIFS(TLX!$E$2:$E$86,TLX!$A$2:$A$86,A86) | H86: =AVERAGEIFS(TLX!$F$2:$F$86,TLX!$A$2:$A$86,A86) | I86: =AVERAGEIFS(TLX!$G$2:$G$86,TLX!$A$2:$A$86,A86) | J86: =IFERROR(AVERAGEIFS(TOAST!$K$2:$K$86,TOAST!$A$2:$A$86,A86),NA()) | K86: =IFERROR(AVERAGEIFS(TOAST!$L$2:$L$86,TOAST!$A$2:$A$86,A86),NA()) | L86: =IFERROR(AVERAGEIFS(TOAST!$M$2:$M$86,TOAST!$A$2:$A$86,A86),NA()) | M86: =AVERAGEIFS(Sessions!$H$2:$H$511,Sessions!$A$2:$A$511,A86) | N86: =AVERAGEIFS(Sessions!$U$2:$U$511,Sessions!$A$2:$A$511,A86) | O86: =AVERAGEIFS(Sessions!$I$2:$I$511,Sessions!$A$2:$A$511,A86) | P86: =_xlfn.RANK.AVG(C86,$C$2:$C$86,1) | Q86: =_xlfn.RANK.AVG(D86,$D$2:$D$86,1) | R86: =_xlfn.RANK.AVG(L86,$L$2:$L$86,1) | S86: =_xlfn.RANK.AVG(M86,$M$2:$M$86,1)

Sheet Analysis
A1: Internal consistency (Cronbach's alpha) -- computed from BIS data
A2: Scale | B2: k items | C2: N rows | D2: Sum of item variances | E2: Variance of total | F2: alpha (computed) | G2: alpha (paper) | H2: |Delta|
A3: SUS (10 items, polarity-adjusted) | B3: 10 | C3: 85 | D3: =_xlfn.VAR.S(SUS!L$2:L$86)+_xlfn.VAR.S(SUS!M$2:M$86)+_xlfn.VAR.S(SUS!N$2:N$86)+_xlfn.VAR.S(SUS!O$2:O$86)+_xlfn.VAR.S(SUS!P$2:P$86)+_xlfn.VAR.S(SUS!Q$2:Q$86)+_xlfn.VAR.S(SUS!R$2:R$86)+_xlfn.VAR.S(SUS!S$2:S$86)+_xlfn.VAR.S(SUS!T$2:T$86)+_xlfn.VAR.S(SUS!U$2:U$86) | E3: =_xlfn.VAR.S(SUS!V$2:V$86) | F3: =(10/9)*(1-D3/E3) | G3: 0.829 | H3: =ABS(F3-G3)
A4: NASA-TLX (5 subscales, no physical demand) | B4: 5 | C4: 85 | D4: =_xlfn.VAR.S(TLX!B$2:B$86)+_xlfn.VAR.S(TLX!D$2:D$86)+_xlfn.VAR.S(TLX!E$2:E$86)+_xlfn.VAR.S(TLX!F$2:F$86)+_xlfn.VAR.S(TLX!G$2:G$86) | E4: =36*_xlfn.VAR.S(TLX!H$2:H$86) | F4: =(5/4)*(1-D4/E4) | G4: 0.812 | H4: =ABS(F4-G4)
A5: TOAST overall (9 items) | B5: 9 | C5: 85 | D5: =_xlfn.VAR.S(TOAST!B$2:B$86)+_xlfn.VAR.S(TOAST!C$2:C$86)+_xlfn.VAR.S(TOAST!D$2:D$86)+_xlfn.VAR.S(TOAST!E$2:E$86)+_xlfn.VAR.S(TOAST!F$2:F$86)+_xlfn.VAR.S(TOAST!G$2:G$86)+_xlfn.VAR.S(TOAST!H$2:H$86)+_xlfn.VAR.S(TOAST!I$2:I$86)+_xlfn.VAR.S(TOAST!J$2:J$86) | E5: =81*_xlfn.VAR.S(TOAST!M$2:M$86) | F5: =(9/8)*(1-D5/E5) | G5: 0.862 | H5: =ABS(F5-G5)
A6: TOAST Understanding (items 1-4) | B6: 4 | C6: 85 | D6: =_xlfn.VAR.S(TOAST!B$2:B$86)+_xlfn.VAR.S(TOAST!C$2:C$86)+_xlfn.VAR.S(TOAST!D$2:D$86)+_xlfn.VAR.S(TOAST!E$2:E$86) | E6: =_xlfn.VAR.S(TOAST!O$2:O$86) | F6: =(4/3)*(1-D6/E6) | G6: 0.815 | H6: =ABS(F6-G6)
A7: TOAST Performance (items 2, 5, 6, 7, 9) | B7: 5 | C7: 85 | D7: =_xlfn.VAR.S(TOAST!C$2:C$86)+_xlfn.VAR.S(TOAST!F$2:F$86)+_xlfn.VAR.S(TOAST!G$2:G$86)+_xlfn.VAR.S(TOAST!H$2:H$86)+_xlfn.VAR.S(TOAST!J$2:J$86) | E7: =25*_xlfn.VAR.S(TOAST!L$2:L$86) | F7: =(5/4)*(1-D7/E7) | G7: 0.809 | H7: =ABS(F7-G7)
A9: Between-group comparisons (Expert vs Non-expert, Table 4)
A10: Measure | B10: Group | C10: N | D10: Mean (computed) | E10: Mean (paper) | F10: |Delta M| | G10: SD | H10: 95% CI low | I10: 95% CI high | J10: Cohen's d (computed) | K10: Cohen's d (paper) | L10: |Delta d| | M10: Mann-Whitney U | N10: z | O10: p (two-sided)
A11: SUS Score (0-100) | B11: Expert | C11: =COUNTIFS(PerParticipant!$B$2:$B$86,"expert",PerParticipant!$C$2:$C$86,"<>") | D11: =AVERAGEIFS(PerParticipant!$C$2:$C$86,PerParticipant!$B$2:$B$86,"expert") | E11: 71.6 | F11: =ABS(D11-E11) | G11: =SQRT(SUMPRODUCT((PerParticipant!$B$2:$B$86="expert")*ISNUMBER(PerParticipant!$C$2:$C$86)*(PerParticipant!$C$2:$C$86-AVERAGEIFS(PerParticipant!$C$2:$C$86,PerParticipant!$B$2:$B$86,"expert"))^2)/(C11-1)) | H11: =D11-_xlfn.T.INV.2T(0.05,C11-1)*G11/SQRT(C11) | I11: =D11+_xlfn.T.INV.2T(0.05,C11-1)*G11/SQRT(C11)
A12: SUS Score (0-100) | B12: Non-expert | C12: =COUNTIFS(PerParticipant!$B$2:$B$86,"non_expert",PerParticipant!$C$2:$C$86,"<>") | D12: =AVERAGEIFS(PerParticipant!$C$2:$C$86,PerParticipant!$B$2:$B$86,"non_expert") | E12: 66.6 | F12: =ABS(D12-E12) | G12: =SQRT(SUMPRODUCT((PerParticipant!$B$2:$B$86="non_expert")*ISNUMBER(PerParticipant!$C$2:$C$86)*(PerParticipant!$C$2:$C$86-AVERAGEIFS(PerParticipant!$C$2:$C$86,PerParticipant!$B$2:$B$86,"non_expert"))^2)/(C12-1)) | H12: =D12-_xlfn.T.INV.2T(0.05,C12-1)*G12/SQRT(C12) | I12: =D12+_xlfn.T.INV.2T(0.05,C12-1)*G12/SQRT(C12) | J12: =(D11-D12)/SQRT(((C11-1)*G11^2+(C12-1)*G12^2)/(C11+C12-2)) | K12: 0.34 | L12: =ABS(J12-K12) | M12: =MIN((SUMIFS(PerParticipant!$P$2:$P$86,PerParticipant!$B$2:$B$86,"expert")-C11*(C11+1)/2),(C11*C12-(SUMIFS(PerParticipant!$P$2:$P$86,PerParticipant!$B$2:$B$86,"expert")-C11*(C11+1)/2))) | N12: =(MIN((SUMIFS(PerParticipant!$P$2:$P$86,PerParticipant!$B$2:$B$86,"expert")-C11*(C11+1)/2),(C11*C12-(SUMIFS(PerParticipant!$P$2:$P$86,PerParticipant!$B$2:$B$86,"expert")-C11*(C11+1)/2)))-(C11*C12/2))/SQRT(C11*C12*(C11+C12+1)/12) | O12: =2*_xlfn.NORM.S.DIST(-ABS(N12),TRUE)
A13: Raw TLX Overall | B13: Expert | C13: =COUNTIFS(PerParticipant!$B$2:$B$86,"expert",PerParticipant!$D$2:$D$86,"<>") | D13: =AVERAGEIFS(PerParticipant!$D$2:$D$86,PerParticipant!$B$2:$B$86,"expert") | E13: 20.2 | F13: =ABS(D13-E13) | G13: =SQRT(SUMPRODUCT((PerParticipant!$B$2:$B$86="expert")*ISNUMBER(PerParticipant!$D$2:$D$86)*(PerParticipant!$D$2:$D$86-AVERAGEIFS(PerParticipant!$D$2:$D$86,PerParticipant!$B$2:$B$86,"expert"))^2)/(C13-1)) | H13: =D13-_xlfn.T.INV.2T(0.05,C13-1)*G13/SQRT(C13) | I13: =D13+_xlfn.T.INV.2T(0.05,C13-1)*G13/SQRT(C13)
A14: Raw TLX Overall | B14: Non-expert | C14: =COUNTIFS(PerParticipant!$B$2:$B$86,"non_expert",PerParticipant!$D$2:$D$86,"<>") | D14: =AVERAGEIFS(PerParticipant!$D$2:$D$86,PerParticipant!$B$2:$B$86,"non_expert") | E14: 29.2 | F14: =ABS(D14-E14) | G14: =SQRT(SUMPRODUCT((PerParticipant!$B$2:$B$86="non_expert")*ISNUMBER(PerParticipant!$D$2:$D$86)*(PerParticipant!$D$2:$D$86-AVERAGEIFS(PerParticipant!$D$2:$D$86,PerParticipant!$B$2:$B$86,"non_expert"))^2)/(C14-1)) | H14: =D14-_xlfn.T.INV.2T(0.05,C14-1)*G14/SQRT(C14) | I14: =D14+_xlfn.T.INV.2T(0.05,C14-1)*G14/SQRT(C14) | J14: =(D13-D14)/SQRT(((C13-1)*G13^2+(C14-1)*G14^2)/(C13+C14-2)) | K14: -0.59 | L14: =ABS(J14-K14) | M14: =MIN((SUMIFS(PerParticipant!$Q$2:$Q$86,PerParticipant!$B$2:$B$86,"expert")-C13*(C13+1)/2),(C13*C14-(SUMIFS(PerParticipant!$Q$2:$Q$86,PerParticipant!$B$2:$B$86,"expert")-C13*(C13+1)/2))) | N14: =(MIN((SUMIFS(PerParticipant!$Q$2:$Q$86,PerParticipant!$B$2:$B$86,"expert")-C13*(C13+1)/2),(C13*C14-(SUMIFS(PerParticipant!$Q$2:$Q$86,PerParticipant!$B$2:$B$86,"expert")-C13*(C13+1)/2)))-(C13*C14/2))/SQRT(C13*C14*(C13+C14+1)/12) | O14: =2*_xlfn.NORM.S.DIST(-ABS(N14),TRUE)
A15: TLX Mental Demand | B15: Expert | C15: =COUNTIFS(PerParticipant!$B$2:$B$86,"expert",PerParticipant!$E$2:$E$86,"<>") | D15: =AVERAGEIFS(PerParticipant!$E$2:$E$86,PerParticipant!$B$2:$B$86,"expert") | E15: 21.3 | F15: =ABS(D15-E15) | G15: =SQRT(SUMPRODUCT((PerParticipant!$B$2:$B$86="expert")*ISNUMBER(PerParticipant!$E$2:$E$86)*(PerParticipant!$E$2:$E$86-AVERAGEIFS(PerParticipant!$E$2:$E$86,PerParticipant!$B$2:$B$86,"expert"))^2)/(C15-1)) | H15: =D15-_xlfn.T.INV.2T(0.05,C15-1)*G15/SQRT(C15) | I15: =D15+_xlfn.T.INV.2T(0.05,C15-1)*G15/SQRT(C15)
A16: TLX Mental Demand | B16: Non-expert | C16: =COUNTIFS(PerParticipant!$B$2:$B$86,"non_expert",PerParticipant!$E$2:$E$86,"<>") | D16: =AVERAGEIFS(PerParticipant!$E$2:$E$86,PerParticipant!$B$2:$B$86,"non_expert") | E16: 34.2 | F16: =ABS(D16-E16) | G16: =SQRT(SUMPRODUCT((PerParticipant!$B$2:$B$86="non_expert")*ISNUMBER(PerParticipant!$E$2:$E$86)*(PerParticipant!$E$2:$E$86-AVERAGEIFS(PerParticipant!$E$2:$E$86,PerParticipant!$B$2:$B$86,"non_expert"))^2)/(C16-1)) | H16: =D16-_xlfn.T.INV.2T(0.05,C16-1)*G16/SQRT(C16) | I16: =D16+_xlfn.T.INV.2T(0.05,C16-1)*G16/SQRT(C16) | J16: =(D15-D16)/SQRT(((C15-1)*G15^2+(C16-1)*G16^2)/(C15+C16-2)) | K16: -0.56 | L16: =ABS(J16-K16)
A17: TLX Temporal Demand | B17: Expert | C17: =COUNTIFS(PerParticipant!$B$2:$B$86,"expert",PerParticipant!$F$2:$F$86,"<>") | D17: =AVERAGEIFS(PerParticipant!$F$2:$F$86,PerParticipant!$B$2:$B$86,"expert") | E17: 12.8 | F17: =ABS(D17-E17) | G17: =SQRT(SUMPRODUCT((PerParticipant!$B$2:$B$86="expert")*ISNUMBER(PerParticipant!$F$2:$F$86)*(PerParticipant!$F$2:$F$86-AVERAGEIFS(PerParticipant!$F$2:$F$86,PerParticipant!$B$2:$B$86,"expert"))^2)/(C17-1)) | H17: =D17-_xlfn.T.INV.2T(0.05,C17-1)*G17/SQRT(C17) | I17: =D17+_xlfn.T.INV.2T(0.05,C17-1)*G17/SQRT(C17)
A18: TLX Temporal Demand | B18: Non-expert | C18: =COUNTIFS(PerParticipant!$B$2:$B$86,"non_expert",PerParticipant!$F$2:$F$86,"<>") | D18: =AVERAGEIFS(PerParticipant!$F$2:$F$86,PerParticipant!$B$2:$B$86,"non_expert") | E18: 26.8 | F18: =ABS(D18-E18) | G18: =SQRT(SUMPRODUCT((PerParticipant!$B$2:$B$86="non_expert")*ISNUMBER(PerParticipant!$F$2:$F$86)*(PerParticipant!$F$2:$F$86-AVERAGEIFS(PerParticipant!$F$2:$F$86,PerParticipant!$B$2:$B$86,"non_expert"))^2)/(C18-1)) | H18: =D18-_xlfn.T.INV.2T(0.05,C18-1)*G18/SQRT(C18) | I18: =D18+_xlfn.T.INV.2T(0.05,C18-1)*G18/SQRT(C18) | J18: =(D17-D18)/SQRT(((C17-1)*G17^2+(C18-1)*G18^2)/(C17+C18-2)) | K18: -0.59 | L18: =ABS(J18-K18)
A19: TLX Performance | B19: Expert | C19: =COUNTIFS(PerParticipant!$B$2:$B$86,"expert",PerParticipant!$G$2:$G$86,"<>") | D19: =AVERAGEIFS(PerParticipant!$G$2:$G$86,PerParticipant!$B$2:$B$86,"expert") | E19: 53.1 | F19: =ABS(D19-E19) | G19: =SQRT(SUMPRODUCT((PerParticipant!$B$2:$B$86="expert")*ISNUMBER(PerParticipant!$G$2:$G$86)*(PerParticipant!$G$2:$G$86-AVERAGEIFS(PerParticipant!$G$2:$G$86,PerParticipant!$B$2:$B$86,"expert"))^2)/(C19-1)) | H19: =D19-_xlfn.T.INV.2T(0.05,C19-1)*G19/SQRT(C19) | I19: =D19+_xlfn.T.INV.2T(0.05,C19-1)*G19/SQRT(C19)
A20: TLX Performance | B20: Non-expert | C20: =COUNTIFS(PerParticipant!$B$2:$B$86,"non_expert",PerParticipant!$G$2:$G$86,"<>") | D20: =AVERAGEIFS(PerParticipant!$G$2:$G$86,PerParticipant!$B$2:$B$86,"non_expert") | E20: 62.6 | F20: =ABS(D20-E20) | G20: =SQRT(SUMPRODUCT((PerParticipant!$B$2:$B$86="non_expert")*ISNUMBER(PerParticipant!$G$2:$G$86)*(PerParticipant!$G$2:$G$86-AVERAGEIFS(PerParticipant!$G$2:$G$86,PerParticipant!$B$2:$B$86,"non_expert"))^2)/(C20-1)) | H20: =D20-_xlfn.T.INV.2T(0.05,C20-1)*G20/SQRT(C20) | I20: =D20+_xlfn.T.INV.2T(0.05,C20-1)*G20/SQRT(C20) | J20: =(D19-D20)/SQRT(((C19-1)*G19^2+(C20-1)*G20^2)/(C19+C20-2)) | K20: -0.33 | L20: =ABS(J20-K20)
A21: TLX Effort | B21: Expert | C21: =COUNTIFS(PerParticipant!$B$2:$B$86,"expert",PerParticipant!$H$2:$H$86,"<>") | D21: =AVERAGEIFS(PerParticipant!$H$2:$H$86,PerParticipant!$B$2:$B$86,"expert") | E21: 20.3 | F21: =ABS(D21-E21) | G21: =SQRT(SUMPRODUCT((PerParticipant!$B$2:$B$86="expert")*ISNUMBER(PerParticipant!$H$2:$H$86)*(PerParticipant!$H$2:$H$86-AVERAGEIFS(PerParticipant!$H$2:$H$86,PerParticipant!$B$2:$B$86,"expert"))^2)/(C21-1)) | H21: =D21-_xlfn.T.INV.2T(0.05,C21-1)*G21/SQRT(C21) | I21: =D21+_xlfn.T.INV.2T(0.05,C21-1)*G21/SQRT(C21)
A22: TLX Effort | B22: Non-expert | C22: =COUNTIFS(PerParticipant!$B$2:$B$86,"non_expert",PerParticipant!$H$2:$H$86,"<>") | D22: =AVERAGEIFS(PerParticipant!$H$2:$H$86,PerParticipant!$B$2:$B$86,"non_expert") | E22: 28.7 | F22: =ABS(D22-E22) | G22: =SQRT(SUMPRODUCT((PerParticipant!$B$2:$B$86="non_expert")*ISNUMBER(PerParticipant!$H$2:$H$86)*(PerParticipant!$H$2:$H$86-AVERAGEIFS(PerParticipant!$H$2:$H$86,PerParticipant!$B$2:$B$86,"non_expert"))^2)/(C22-1)) | H22: =D22-_xlfn.T.INV.2T(0.05,C22-1)*G22/SQRT(C22) | I22: =D22+_xlfn.T.INV.2T(0.05,C22-1)*G22/SQRT(C22) | J22: =(D21-D22)/SQRT(((C21-1)*G21^2+(C22-1)*G22^2)/(C21+C22-2)) | K22: -0.37 | L22: =ABS(J22-K22)
A23: TLX Frustration | B23: Expert | C23: =COUNTIFS(PerParticipant!$B$2:$B$86,"expert",PerParticipant!$I$2:$I$86,"<>") | D23: =AVERAGEIFS(PerParticipant!$I$2:$I$86,PerParticipant!$B$2:$B$86,"expert") | E23: 13.4 | F23: =ABS(D23-E23) | G23: =SQRT(SUMPRODUCT((PerParticipant!$B$2:$B$86="expert")*ISNUMBER(PerParticipant!$I$2:$I$86)*(PerParticipant!$I$2:$I$86-AVERAGEIFS(PerParticipant!$I$2:$I$86,PerParticipant!$B$2:$B$86,"expert"))^2)/(C23-1)) | H23: =D23-_xlfn.T.INV.2T(0.05,C23-1)*G23/SQRT(C23) | I23: =D23+_xlfn.T.INV.2T(0.05,C23-1)*G23/SQRT(C23)
A24: TLX Frustration | B24: Non-expert | C24: =COUNTIFS(PerParticipant!$B$2:$B$86,"non_expert",PerParticipant!$I$2:$I$86,"<>") | D24: =AVERAGEIFS(PerParticipant!$I$2:$I$86,PerParticipant!$B$2:$B$86,"non_expert") | E24: 22.7 | F24: =ABS(D24-E24) | G24: =SQRT(SUMPRODUCT((PerParticipant!$B$2:$B$86="non_expert")*ISNUMBER(PerParticipant!$I$2:$I$86)*(PerParticipant!$I$2:$I$86-AVERAGEIFS(PerParticipant!$I$2:$I$86,PerParticipant!$B$2:$B$86,"non_expert"))^2)/(C24-1)) | H24: =D24-_xlfn.T.INV.2T(0.05,C24-1)*G24/SQRT(C24) | I24: =D24+_xlfn.T.INV.2T(0.05,C24-1)*G24/SQRT(C24) | J24: =(D23-D24)/SQRT(((C23-1)*G23^2+(C24-1)*G24^2)/(C23+C24-2)) | K24: -0.44 | L24: =ABS(J24-K24)
A25: TOAST Understanding (1-7) | B25: Expert | C25: =COUNTIFS(PerParticipant!$B$2:$B$86,"expert",PerParticipant!$J$2:$J$86,"<>") | D25: =AVERAGEIFS(PerParticipant!$J$2:$J$86,PerParticipant!$B$2:$B$86,"expert") | E25: 5.32 | F25: =ABS(D25-E25) | G25: =SQRT(SUMPRODUCT((PerParticipant!$B$2:$B$86="expert")*ISNUMBER(PerParticipant!$J$2:$J$86)*(PerParticipant!$J$2:$J$86-AVERAGEIFS(PerParticipant!$J$2:$J$86,PerParticipant!$B$2:$B$86,"expert"))^2)/(C25-1)) | H25: =D25-_xlfn.T.INV.2T(0.05,C25-1)*G25/SQRT(C25) | I25: =D25+_xlfn.T.INV.2T(0.05,C25-1)*G25/SQRT(C25)
A26: TOAST Understanding (1-7) | B26: Non-expert | C26: =COUNTIFS(PerParticipant!$B$2:$B$86,"non_expert",PerParticipant!$J$2:$J$86,"<>") | D26: =AVERAGEIFS(PerParticipant!$J$2:$J$86,PerParticipant!$B$2:$B$86,"non_expert") | E26: 4.87 | F26: =ABS(D26-E26) | G26: =SQRT(SUMPRODUCT((PerParticipant!$B$2:$B$86="non_expert")*ISNUMBER(PerParticipant!$J$2:$J$86)*(PerParticipant!$J$2:$J$86-AVERAGEIFS(PerParticipant!$J$2:$J$86,PerParticipant!$B$2:$B$86,"non_expert"))^2)/(C26-1)) | H26: =D26-_xlfn.T.INV.2T(0.05,C26-1)*G26/SQRT(C26) | I26: =D26+_xlfn.T.INV.2T(0.05,C26-1)*G26/SQRT(C26) | J26: =(D25-D26)/SQRT(((C25-1)*G25^2+(C26-1)*G26^2)/(C25+C26-2)) | K26: 0.55 | L26: =ABS(J26-K26)
A27: TOAST Performance (1-7) | B27: Expert | C27: =COUNTIFS(PerParticipant!$B$2:$B$86,"expert",PerParticipant!$K$2:$K$86,"<>") | D27: =AVERAGEIFS(PerParticipant!$K$2:$K$86,PerParticipant!$B$2:$B$86,"expert") | E27: 5.34 | F27: =ABS(D27-E27) | G27: =SQRT(SUMPRODUCT((PerParticipant!$B$2:$B$86="expert")*ISNUMBER(PerParticipant!$K$2:$K$86)*(PerParticipant!$K$2:$K$86-AVERAGEIFS(PerParticipant!$K$2:$K$86,PerParticipant!$B$2:$B$86,"expert"))^2)/(C27-1)) | H27: =D27-_xlfn.T.INV.2T(0.05,C27-1)*G27/SQRT(C27) | I27: =D27+_xlfn.T.INV.2T(0.05,C27-1)*G27/SQRT(C27)
A28: TOAST Performance (1-7) | B28: Non-expert | C28: =COUNTIFS(PerParticipant!$B$2:$B$86,"non_expert",PerParticipant!$K$2:$K$86,"<>") | D28: =AVERAGEIFS(PerParticipant!$K$2:$K$86,PerParticipant!$B$2:$B$86,"non_expert") | E28: 5.05 | F28: =ABS(D28-E28) | G28: =SQRT(SUMPRODUCT((PerParticipant!$B$2:$B$86="non_expert")*ISNUMBER(PerParticipant!$K$2:$K$86)*(PerParticipant!$K$2:$K$86-AVERAGEIFS(PerParticipant!$K$2:$K$86,PerParticipant!$B$2:$B$86,"non_expert"))^2)/(C28-1)) | H28: =D28-_xlfn.T.INV.2T(0.05,C28-1)*G28/SQRT(C28) | I28: =D28+_xlfn.T.INV.2T(0.05,C28-1)*G28/SQRT(C28) | J28: =(D27-D28)/SQRT(((C27-1)*G27^2+(C28-1)*G28^2)/(C27+C28-2)) | K28: 0.36 | L28: =ABS(J28-K28)
A29: TOAST Overall (1-7) | B29: Expert | C29: =COUNTIFS(PerParticipant!$B$2:$B$86,"expert",PerParticipant!$L$2:$L$86,"<>") | D29: =AVERAGEIFS(PerParticipant!$L$2:$L$86,PerParticipant!$B$2:$B$86,"expert") | E29: 5.33 | F29: =ABS(D29-E29) | G29: =SQRT(SUMPRODUCT((PerParticipant!$B$2:$B$86="expert")*ISNUMBER(PerParticipant!$L$2:$L$86)*(PerParticipant!$L$2:$L$86-AVERAGEIFS(PerParticipant!$L$2:$L$86,PerParticipant!$B$2:$B$86,"expert"))^2)/(C29-1)) | H29: =D29-_xlfn.T.INV.2T(0.05,C29-1)*G29/SQRT(C29) | I29: =D29+_xlfn.T.INV.2T(0.05,C29-1)*G29/SQRT(C29)
A30: TOAST Overall (1-7) | B30: Non-expert | C30: =COUNTIFS(PerParticipant!$B$2:$B$86,"non_expert",PerParticipant!$L$2:$L$86,"<>") | D30: =AVERAGEIFS(PerParticipant!$L$2:$L$86,PerParticipant!$B$2:$B$86,"non_expert") | E30: 4.97 | F30: =ABS(D30-E30) | G30: =SQRT(SUMPRODUCT((PerParticipant!$B$2:$B$86="non_expert")*ISNUMBER(PerParticipant!$L$2:$L$86)*(PerParticipant!$L$2:$L$86-AVERAGEIFS(PerParticipant!$L$2:$L$86,PerParticipant!$B$2:$B$86,"non_expert"))^2)/(C30-1)) | H30: =D30-_xlfn.T.INV.2T(0.05,C30-1)*G30/SQRT(C30) | I30: =D30+_xlfn.T.INV.2T(0.05,C30-1)*G30/SQRT(C30) | J30: =(D29-D30)/SQRT(((C29-1)*G29^2+(C30-1)*G30^2)/(C29+C30-2)) | K30: 0.47 | L30: =ABS(J30-K30) | M30: =MIN((SUMIFS(PerParticipant!$R$2:$R$86,PerParticipant!$B$2:$B$86,"expert")-C29*(C29+1)/2),(C29*C30-(SUMIFS(PerParticipant!$R$2:$R$86,PerParticipant!$B$2:$B$86,"expert")-C29*(C29+1)/2))) | N30: =(MIN((SUMIFS(PerParticipant!$R$2:$R$86,PerParticipant!$B$2:$B$86,"expert")-C29*(C29+1)/2),(C29*C30-(SUMIFS(PerParticipant!$R$2:$R$86,PerParticipant!$B$2:$B$86,"expert")-C29*(C29+1)/2)))-(C29*C30/2))/SQRT(C29*C30*(C29+C30+1)/12) | O30: =2*_xlfn.NORM.S.DIST(-ABS(N30),TRUE)
A32: Behavioural outcomes (Table 5)
A33: Group | B33: Complexity | C33: N sessions | D33: Success rate (computed, %) | E33: Success rate (paper, %) | F33: |Delta| | G33: Avg attempts (computed) | H33: Avg attempts (paper) | I33: |Delta| | J33: Avg time s (computed) | K33: Avg time s (paper) | L33: |Delta|
A34: Non-expert | B34: C1 | C34: =COUNTIFS(Sessions!$V$2:$V$511,"non_expert",Sessions!$C$2:$C$511,"C1") | D34: =AVERAGEIFS(Sessions!$U$2:$U$511,Sessions!$V$2:$V$511,"non_expert",Sessions!$C$2:$C$511,"C1")*100 | E34: 98.9 | F34: =ABS(D34-E34) | G34: =AVERAGEIFS(Sessions!$I$2:$I$511,Sessions!$V$2:$V$511,"non_expert",Sessions!$C$2:$C$511,"C1") | H34: 1.54 | I34: =ABS(G34-H34) | J34: =AVERAGEIFS(Sessions!$H$2:$H$511,Sessions!$V$2:$V$511,"non_expert",Sessions!$C$2:$C$511,"C1") | K34: 126 | L34: =ABS(J34-K34)
A35: Non-expert | B35: C2 | C35: =COUNTIFS(Sessions!$V$2:$V$511,"non_expert",Sessions!$C$2:$C$511,"C2") | D35: =AVERAGEIFS(Sessions!$U$2:$U$511,Sessions!$V$2:$V$511,"non_expert",Sessions!$C$2:$C$511,"C2")*100 | E35: 94.4 | F35: =ABS(D35-E35) | G35: =AVERAGEIFS(Sessions!$I$2:$I$511,Sessions!$V$2:$V$511,"non_expert",Sessions!$C$2:$C$511,"C2") | H35: 1.6 | I35: =ABS(G35-H35) | J35: =AVERAGEIFS(Sessions!$H$2:$H$511,Sessions!$V$2:$V$511,"non_expert",Sessions!$C$2:$C$511,"C2") | K35: 134 | L35: =ABS(J35-K35)
